Workbook
Name angled_rod_sep_: 'Slice Position'!$B$9
Name B0_: 'BC SNR'!$B$24
Name B0_: 'HC SNR'!$B$24
Name BW_: 'BC SNR'!$B$29
Name BW_: 'HC SNR'!$B$29
Name BW_nominal_: 'BC SNR'!$B$37
Name BW_nominal_: 'HC SNR'!$B$37
Name BW_norm_: 'BC SNR'!$B$40
Name BW_norm_: 'HC SNR'!$B$40
Name BW_scanner_: 'BC SNR'!$B$22
Name BW_scanner_: 'HC SNR'!$B$22
Name CL_norm_: 'BC SNR'!$B$45
Name CL_norm_: 'HC SNR'!$B$45
Name Dx_: 'BC SNR'!$B$30
Name Dx_: 'HC SNR'!$B$30
Name Dx_: 'Slice Width'!$B$16
Name Dy_: 'BC SNR'!$B$31
Name Dy_: 'HC SNR'!$B$31
Name Dz_cor_: 'BC SNR'!$B$34
Name Dz_cor_: 'HC SNR'!$B$34
Name Dz_sag_: 'BC SNR'!$B$33
Name Dz_sag_: 'HC SNR'!$B$33
Name Dz_tra_: 'BC SNR'!$B$32
Name Dz_tra_: 'HC SNR'!$B$32
Name FOV_: 'BC SNR'!$B$21
Name FOV_: 'HC SNR'!$B$21
Name FOV_: 'Slice Width'!$B$9
Name FWHM_cor_1_: 'Slice Width'!$B$21
Name FWHM_cor_2_: 'Slice Width'!$B$22
Name FWHM_sag_1_: 'Slice Width'!$B$19
Name FWHM_sag_2_: 'Slice Width'!$B$20
Name FWHM_tra_1_: 'Slice Width'!$B$17
Name FWHM_tra_2_: 'Slice Width'!$B$18
Name N_fe_: 'BC SNR'!$B$18
Name N_fe_: 'HC SNR'!$B$18
Name N_fe_: 'Slice Width'!$B$8
Name N_pe_: 'BC SNR'!$B$17
Name N_pe_: 'HC SNR'!$B$17
Name NSA_: 'BC SNR'!$B$20
Name NSA_: 'HC SNR'!$B$20
Name profile_1_baseline_offset_: 'Cor Slice Width'!$B$2
Name profile_1_baseline_offset_: 'Sag Slice Width'!$B$2
Name profile_1_baseline_offset_: 'Tra Slice Width'!$B$2
Name profile_1_min_offset_: 'Cor Slice Width'!$B$3
Name profile_1_min_offset_: 'Sag Slice Width'!$B$3
Name profile_1_min_offset_: 'Tra Slice Width'!$B$3
Name profile_2_baseline_offset_: 'Cor Slice Width'!$B$4
Name profile_2_baseline_offset_: 'Sag Slice Width'!$B$4
Name profile_2_baseline_offset_: 'Tra Slice Width'!$B$4
Name profile_2_min_offset_: 'Cor Slice Width'!$B$5
Name profile_2_min_offset_: 'Sag Slice Width'!$B$5
Name profile_2_min_offset_: 'Tra Slice Width'!$B$5
Name Q_head_: 'BC SNR'!$B$25
Name Q_head_: 'HC SNR'!$B$25
Name Q_test_object_: 'BC SNR'!$B$26
Name Q_test_object_: 'HC SNR'!$B$26
Name rda_: 'Slice Position'!$B$10
Name rod_dist_: Geometric!$B$13
Name Scanner_: 'BC SNR'!$B$23
Name Scanner_: 'HC SNR'!$B$23

Sheet BC SNR
A1: In-built Body Coil SNR
B3: Transverse | C3: Sagittal | D3: Coronal | E3: Mean
A4: Signal to noise ratio | B4: =SNR_tra_ -> #DIV/0! | C4: =SNR_sag_ -> #DIV/0! | D4: =SNR_cor_ -> #DIV/0! | E4: =AVERAGE(B4:D4) -> #DIV/0!
A5: Normalised SNR | B5: =BW_norm_*VS_corr_tra_*ST_corr_*CL_norm_*B4 -> #DIV/0! | C5: =BW_norm_*VS_corr_sag_*ST_corr_*CL_norm_*C4 -> #DIV/0! | D5: =BW_norm_*VS_corr_cor_*ST_corr_*CL_norm_*D4 -> #DIV/0! | E5: =AVERAGE(B5:D5) -> #DIV/0!
A7: Plane: Transverse | E7: Plane: Sagittal | I7: Plane: Coronal
A8: ROI | B8: Signal Mean | C8: Difference Standard Deviation | E8: ROI | F8: Signal Mean | G8: Difference Standard Deviation | I8: ROI | J8: Signal Mean | K8: Difference Standard Deviation
A9: 1 | E9: 1 | I9: 1
A10: 2 | E10: 2 | I10: 2
A11: 3 | E11: 3 | I11: 3
A12: 4 | E12: 4 | I12: 4
A13: 5 | E13: 5 | I13: 5
A14: Signal to noise ratio | B14: =AVERAGE(B9:B13)*SQRT(2)/AVERAGE(C9:C13) -> #DIV/0! | E14: Signal to noise ratio | F14: =AVERAGE(F9:F13)*SQRT(2)/AVERAGE(G9:G13) -> #DIV/0! | I14: Signal to noise ratio | J14: =AVERAGE(J9:J13)*SQRT(2)/AVERAGE(K9:K13) -> #DIV/0!
A16: Input Parameters | B16: Value
A17: Phase encode matrix size | I17: BC_TRA_SNR_Images_with_ROIs
A18: Frequency encode matrix size
A19: Repetition time (ms)
A20: Number of signal averages
A21: Field-of-view (mm)
A22: Bandwidth from scanner interface
A23: Scanner manufacturer | B23: Siemens
A24: Static magnetic field strength (T) | B24: 1.5
A25: Q-factor for head or body | B25: 1
A26: Q-factor for test object | B26: 1
A28: Calculated Parameters | B28: Value
A29: ±Bandwidth (kHz) | B29: =IF(Scanner_="GE",BW_scanner_,IF(Scanner_="Philips",0.5*(B0_*42.5*3.5/1000)*N_fe_/BW_scanner_,IF(Scanner_="Siemens", BW_scanner_*N_fe_/(2*1000),"Error: unrecognised scanner"))) -> 0
A30: Voxel size in the frequency encode direction (mm) | B30: =FOV_/N_fe_ -> #DIV/0!
A31: Voxel size in the phase encode direction (mm) | B31: =FOV_/N_pe_ -> #DIV/0!
A32: Slice width for transverse acquisition (mm) | B32: ='Slice Width'!B5 -> 0 | I32: BC_SAG_SNR_Images_with_ROIs
A33: Slice width for sagittal acquisition (mm) | B33: ='Slice Width'!C5 -> 0
A34: Slice width for coronal acquisition (mm) | B34: ='Slice Width'!D5 -> 0
A36: Fixed Parameters | B36: Value
A37: ±Nominal bandwidth (kHz) | B37: 30
A39: SNR Normalisation Factors | B39: Value
A40: Bandwidth normalisation | B40: =SQRT(BW_/BW_nominal_) -> 0
A41: Voxel size correction (transverse) | B41: =1/((Dx_/10)*(Dy_/10)*(Dz_tra_/10)) -> #DIV/0!
A42: Voxel size correction (sagittal) | B42: =1/((Dx_/10)*(Dy_/10)*(Dz_sag_/10)) -> #DIV/0!
A43: Voxel size correction (coronal) | B43: =1/((Dx_/10)*(Dy_/10)*(Dz_cor_/10)) -> #DIV/0!
A44: Scan time correction | B44: =1/SQRT(N_pe_*(TR_/1000)*NSA_) -> #DIV/0!
A45: Coil loading normalisation | B45: =SQRT(Q_head_/Q_test_object_) -> 1
I47: BC_COR_SNR_Images_with_ROIs
...

Sheet HC SNR
A1: Head Coil SNR
B3: Transverse | C3: Sagittal | D3: Coronal | E3: Mean
A4: Signal to noise ratio | B4: =SNR_tra_ -> #DIV/0! | C4: =SNR_sag_ -> #DIV/0! | D4: =SNR_cor_ -> #DIV/0! | E4: =AVERAGE(B4:D4) -> #DIV/0!
A5: Normalised SNR | B5: =BW_norm_*VS_corr_tra_*ST_corr_*CL_norm_*B4 -> #DIV/0! | C5: =BW_norm_*VS_corr_sag_*ST_corr_*CL_norm_*C4 -> #DIV/0! | D5: =BW_norm_*VS_corr_cor_*ST_corr_*CL_norm_*D4 -> #DIV/0! | E5: =AVERAGE(B5:D5) -> #DIV/0!
A7: Plane: Transverse | E7: Plane: Sagittal | I7: Plane: Coronal
A8: ROI | B8: Signal Mean | C8: Difference Standard Deviation | E8: ROI | F8: Signal Mean | G8: Difference Standard Deviation | I8: ROI | J8: Signal Mean | K8: Difference Standard Deviation
A9: 1 | E9: 1 | I9: 1
A10: 2 | E10: 2 | I10: 2
A11: 3 | E11: 3 | I11: 3
A12: 4 | E12: 4 | I12: 4
A13: 5 | E13: 5 | I13: 5
A14: Signal to noise ratio | B14: =AVERAGE(B9:B13)*SQRT(2)/AVERAGE(C9:C13) -> #DIV/0! | E14: Signal to noise ratio | F14: =AVERAGE(F9:F13)*SQRT(2)/AVERAGE(G9:G13) -> #DIV/0! | I14: Signal to noise ratio | J14: =AVERAGE(J9:J13)*SQRT(2)/AVERAGE(K9:K13) -> #DIV/0!
A16: Input Parameters | B16: Value
A17: Phase encode matrix size | I17: HC_TRA_SNR_Images_with_ROIs
A18: Frequency encode matrix size
A19: Repetition time (ms)
A20: Number of signal averages
A21: Field-of-view (mm)
A22: Bandwidth from scanner interface
A23: Scanner manufacturer | B23: Siemens
A24: Static magnetic field strength (T) | B24: 1.5
A25: Q-factor for head or body | B25: 1
A26: Q-factor for test object | B26: 1
A28: Calculated Parameters | B28: Value
A29: ±Bandwidth (kHz) | B29: =IF(Scanner_="GE",BW_scanner_,IF(Scanner_="Philips",0.5*(B0_*42.5*3.5/1000)*N_fe_/BW_scanner_,IF(Scanner_="Siemens", BW_scanner_*N_fe_/(2*1000),"Error: unrecognised scanner"))) -> 0
A30: Voxel size in the frequency encode direction (mm) | B30: =FOV_/N_fe_ -> #DIV/0!
A31: Voxel size in the phase encode direction (mm) | B31: =FOV_/N_pe_ -> #DIV/0!
A32: Slice width for transverse acquisition (mm) | B32: ='Slice Width'!B5 -> 0 | I32: HC_SAG_SNR_Images_with_ROIs
A33: Slice width for sagittal acquisition (mm) | B33: ='Slice Width'!E5 -> 0
A34: Slice width for coronal acquisition (mm) | B34: ='Slice Width'!D5 -> 0
A36: Fixed Parameters | B36: Value
A37: ±Nominal bandwidth (kHz) | B37: 30
A39: SNR Normalisation Factors | B39: Value
A40: Bandwidth normalisation | B40: =SQRT(BW_/BW_nominal_) -> 0
A41: Voxel size correction (transverse) | B41: =1/((Dx_/10)*(Dy_/10)*(Dz_tra_/10)) -> #DIV/0!
A42: Voxel size correction (sagittal) | B42: =1/((Dx_/10)*(Dy_/10)*(Dz_sag_/10)) -> #DIV/0!
A43: Voxel size correction (coronal) | B43: =1/((Dx_/10)*(Dy_/10)*(Dz_cor_/10)) -> #DIV/0!
A44: Scan time correction | B44: =1/SQRT(N_pe_*(TR_/1000)*NSA_) -> #DIV/0!
A45: Coil loading normalisation | B45: =SQRT(Q_head_/Q_test_object_) -> 1
I47: HC_COR_SNR_Images_with_ROIs
...

Sheet BC Uniformity
A1: In-built Body Coil Uniformity
A3: x-direction | B3: y-direction | C3: z-direction | D3: Average | E3: Standard Deviation
A4: =AVERAGE(B7,D7) -> 0 | B4: =AVERAGE(B8,C7) -> 0 | C4: =AVERAGE(C8,D8) -> 0 | D4: =AVERAGE(A4:C4) -> 0 | E4: =_xlfn.STDEV.S(B7:D8) -> 0
B6: Transverse | C6: Sagittal | D6: Coronal
A7: Horizontal | B7: ='BC Tra Uniformity'!B2 -> 0 | C7: ='BC Sag Uniformity'!B2 -> 0 | D7: ='BC Cor Uniformity'!B2 -> 0
A8: Vertical | B8: ='BC Tra Uniformity'!C2 -> 0 | C8: ='BC Sag Uniformity'!C2 -> 0 | D8: ='BC Cor Uniformity'!C2 -> 0

Sheet BC Tra Uniformity
B1: Horizontal | C1: Vertical
A2: Fractional Uniformity | B2: =COUNTIF(D6:D165, "<"&0.1*C6)/160 -> 0 | C2: =COUNTIF(I6:I165, "<"&0.1*H6)/160 -> 0
A4: Horizontal | F4: Vertical
A5: Pixel | B5: Profile Data | C5: Central ROI Mean | D5: Abs Difference | F5: Pixel | G5: Profile Data | H5: Central ROI Mean | I5: Abs Difference
A6: 1 | D6: =ABS(B6-C6) -> 0 | F6: 1 | I6: =ABS(G6-H6) -> 0
A7: 2 | D7: =ABS(B7-C7) -> 0 | F7: 2 | I7: =ABS(G7-H7) -> 0
A8: 3 | D8: =ABS(B8-C8) -> 0 | F8: 3 | I8: =ABS(G8-H8) -> 0
A9: 4 | D9: =ABS(B9-C9) -> 0 | F9: 4 | I9: =ABS(G9-H9) -> 0
A10: 5 | D10: =ABS(B10-C10) -> 0 | F10: 5 | I10: =ABS(G10-H10) -> 0
A11: 6 | D11: =ABS(B11-C11) -> 0 | F11: 6 | I11: =ABS(G11-H11) -> 0 | S11: BC_TRA_UNIFORMITY_ROIs
A12: 7 | D12: =ABS(B12-C12) -> 0 | F12: 7 | I12: =ABS(G12-H12) -> 0
A13: 8 | D13: =ABS(B13-C13) -> 0 | F13: 8 | I13: =ABS(G13-H13) -> 0
A14: 9 | D14: =ABS(B14-C14) -> 0 | F14: 9 | I14: =ABS(G14-H14) -> 0
A15: 10 | D15: =ABS(B15-C15) -> 0 | F15: 10 | I15: =ABS(G15-H15) -> 0
A16: 11 | D16: =ABS(B16-C16) -> 0 | F16: 11 | I16: =ABS(G16-H16) -> 0
A17: 12 | D17: =ABS(B17-C17) -> 0 | F17: 12 | I17: =ABS(G17-H17) -> 0
A18: 13 | D18: =ABS(B18-C18) -> 0 | F18: 13 | I18: =ABS(G18-H18) -> 0
A19: 14 | D19: =ABS(B19-C19) -> 0 | F19: 14 | I19: =ABS(G19-H19) -> 0
A20: 15 | D20: =ABS(B20-C20) -> 0 | F20: 15 | I20: =ABS(G20-H20) -> 0
A21: 16 | D21: =ABS(B21-C21) -> 0 | F21: 16 | I21: =ABS(G21-H21) -> 0
A22: 17 | D22: =ABS(B22-C22) -> 0 | F22: 17 | I22: =ABS(G22-H22) -> 0
A23: 18 | D23: =ABS(B23-C23) -> 0 | F23: 18 | I23: =ABS(G23-H23) -> 0
... A165: 160 | D165: =ABS(B165-C165) -> 0 | F165: 160 | I165: =ABS(G165-H165) -> 0

Sheet BC Sag Uniformity
B1: Horizontal | C1: Vertical
A2: Fractional Uniformity | B2: =COUNTIF(D6:D165, "<"&0.1*C6)/160 -> 0 | C2: =COUNTIF(I6:I165, "<"&0.1*H6)/160 -> 0
A4: Horizontal | F4: Vertical
A5: Pixel | B5: Profile Data | C5: Central ROI Mean | D5: Abs Difference | F5: Pixel | G5: Profile Data | H5: Central ROI Mean | I5: Abs Difference
A6: 1 | D6: =ABS(B6-C6) -> 0 | F6: 1 | I6: =ABS(G6-H6) -> 0
A7: 2 | D7: =ABS(B7-C7) -> 0 | F7: 2 | I7: =ABS(G7-H7) -> 0
A8: 3 | D8: =ABS(B8-C8) -> 0 | F8: 3 | I8: =ABS(G8-H8) -> 0
A9: 4 | D9: =ABS(B9-C9) -> 0 | F9: 4 | I9: =ABS(G9-H9) -> 0
A10: 5 | D10: =ABS(B10-C10) -> 0 | F10: 5 | I10: =ABS(G10-H10) -> 0
A11: 6 | D11: =ABS(B11-C11) -> 0 | F11: 6 | I11: =ABS(G11-H11) -> 0
A12: 7 | D12: =ABS(B12-C12) -> 0 | F12: 7 | I12: =ABS(G12-H12) -> 0 | S12: BC_SAG_UNIFORMITY_ROIs
A13: 8 | D13: =ABS(B13-C13) -> 0 | F13: 8 | I13: =ABS(G13-H13) -> 0
A14: 9 | D14: =ABS(B14-C14) -> 0 | F14: 9 | I14: =ABS(G14-H14) -> 0
A15: 10 | D15: =ABS(B15-C15) -> 0 | F15: 10 | I15: =ABS(G15-H15) -> 0
A16: 11 | D16: =ABS(B16-C16) -> 0 | F16: 11 | I16: =ABS(G16-H16) -> 0
A17: 12 | D17: =ABS(B17-C17) -> 0 | F17: 12 | I17: =ABS(G17-H17) -> 0
A18: 13 | D18: =ABS(B18-C18) -> 0 | F18: 13 | I18: =ABS(G18-H18) -> 0
A19: 14 | D19: =ABS(B19-C19) -> 0 | F19: 14 | I19: =ABS(G19-H19) -> 0
A20: 15 | D20: =ABS(B20-C20) -> 0 | F20: 15 | I20: =ABS(G20-H20) -> 0
A21: 16 | D21: =ABS(B21-C21) -> 0 | F21: 16 | I21: =ABS(G21-H21) -> 0
A22: 17 | D22: =ABS(B22-C22) -> 0 | F22: 17 | I22: =ABS(G22-H22) -> 0
A23: 18 | D23: =ABS(B23-C23) -> 0 | F23: 18 | I23: =ABS(G23-H23) -> 0
A24: 19 | D24: =ABS(B24-C24) -> 0 | F24: 19 | I24: =ABS(G24-H24) -> 0
... A165: 160 | D165: =ABS(B165-C165) -> 0 | F165: 160 | I165: =ABS(G165-H165) -> 0

Sheet BC Cor Uniformity
B1: Horizontal | C1: Vertical
A2: Fractional Uniformity | B2: =COUNTIF(D6:D165, "<"&0.1*C6)/160 -> 0 | C2: =COUNTIF(I6:I165, "<"&0.1*H6)/160 -> 0
A4: Horizontal | F4: Vertical
A5: Pixel | B5: Profile Data | C5: Central ROI Mean | D5: Abs Difference | F5: Pixel | G5: Profile Data | H5: Central ROI Mean | I5: Abs Difference
A6: 1 | D6: =ABS(B6-C6) -> 0 | F6: 1 | I6: =ABS(G6-H6) -> 0
A7: 2 | D7: =ABS(B7-C7) -> 0 | F7: 2 | I7: =ABS(G7-H7) -> 0
A8: 3 | D8: =ABS(B8-C8) -> 0 | F8: 3 | I8: =ABS(G8-H8) -> 0
A9: 4 | D9: =ABS(B9-C9) -> 0 | F9: 4 | I9: =ABS(G9-H9) -> 0
A10: 5 | D10: =ABS(B10-C10) -> 0 | F10: 5 | I10: =ABS(G10-H10) -> 0
A11: 6 | D11: =ABS(B11-C11) -> 0 | F11: 6 | I11: =ABS(G11-H11) -> 0
A12: 7 | D12: =ABS(B12-C12) -> 0 | F12: 7 | I12: =ABS(G12-H12) -> 0 | S12: BC_COR_UNIFORMITY_ROIs
A13: 8 | D13: =ABS(B13-C13) -> 0 | F13: 8 | I13: =ABS(G13-H13) -> 0
A14: 9 | D14: =ABS(B14-C14) -> 0 | F14: 9 | I14: =ABS(G14-H14) -> 0
A15: 10 | D15: =ABS(B15-C15) -> 0 | F15: 10 | I15: =ABS(G15-H15) -> 0
A16: 11 | D16: =ABS(B16-C16) -> 0 | F16: 11 | I16: =ABS(G16-H16) -> 0
A17: 12 | D17: =ABS(B17-C17) -> 0 | F17: 12 | I17: =ABS(G17-H17) -> 0
A18: 13 | D18: =ABS(B18-C18) -> 0 | F18: 13 | I18: =ABS(G18-H18) -> 0
A19: 14 | D19: =ABS(B19-C19) -> 0 | F19: 14 | I19: =ABS(G19-H19) -> 0
A20: 15 | D20: =ABS(B20-C20) -> 0 | F20: 15 | I20: =ABS(G20-H20) -> 0
A21: 16 | D21: =ABS(B21-C21) -> 0 | F21: 16 | I21: =ABS(G21-H21) -> 0
A22: 17 | D22: =ABS(B22-C22) -> 0 | F22: 17 | I22: =ABS(G22-H22) -> 0
A23: 18 | D23: =ABS(B23-C23) -> 0 | F23: 18 | I23: =ABS(G23-H23) -> 0
A24: 19 | D24: =ABS(B24-C24) -> 0 | F24: 19 | I24: =ABS(G24-H24) -> 0
... A165: 160 | D165: =ABS(B165-C165) -> 0 | F165: 160 | I165: =ABS(G165-H165) -> 0

Sheet HC Uniformity
A1: Head Coil Uniformity
A3: x-direction | B3: y-direction | C3: z-direction | D3: Average | E3: Standard Deviation
A4: =AVERAGE(B7,D7) -> 0 | B4: =AVERAGE(B8,C7) -> 0 | C4: =AVERAGE(C8,D8) -> 0 | D4: =AVERAGE(A4:C4) -> 0 | E4: =_xlfn.STDEV.S(B7:D8) -> 0
B6: Transverse | C6: Sagittal | D6: Coronal
A7: Horizontal | B7: ='HC Tra Uniformity'!B2 -> 0 | C7: ='HC Sag Uniformity'!B2 -> 0 | D7: ='HC Cor Uniformity'!B2 -> 0
A8: Vertical | B8: ='HC Tra Uniformity'!C2 -> 0 | C8: ='HC Sag Uniformity'!C2 -> 0 | D8: ='HC Cor Uniformity'!C2 -> 0

Sheet HC Tra Uniformity
B1: Horizontal | C1: Vertical
A2: Fractional Uniformity | B2: =COUNTIF(D6:D165, "<"&0.1*C6)/160 -> 0 | C2: =COUNTIF(I6:I165, "<"&0.1*H6)/160 -> 0
A4: Horizontal | F4: Vertical
A5: Pixel | B5: Profile Data | C5: Central ROI Mean | D5: Abs Difference | F5: Pixel | G5: Profile Data | H5: Central ROI Mean | I5: Abs Difference
A6: 1 | D6: =ABS(B6-C6) -> 0 | F6: 1 | I6: =ABS(G6-H6) -> 0
A7: 2 | D7: =ABS(B7-C7) -> 0 | F7: 2 | I7: =ABS(G7-H7) -> 0
A8: 3 | D8: =ABS(B8-C8) -> 0 | F8: 3 | I8: =ABS(G8-H8) -> 0
A9: 4 | D9: =ABS(B9-C9) -> 0 | F9: 4 | I9: =ABS(G9-H9) -> 0
A10: 5 | D10: =ABS(B10-C10) -> 0 | F10: 5 | I10: =ABS(G10-H10) -> 0
A11: 6 | D11: =ABS(B11-C11) -> 0 | F11: 6 | I11: =ABS(G11-H11) -> 0
A12: 7 | D12: =ABS(B12-C12) -> 0 | F12: 7 | I12: =ABS(G12-H12) -> 0 | S12: HC_TRA_UNIFORMITY_ROIs
A13: 8 | D13: =ABS(B13-C13) -> 0 | F13: 8 | I13: =ABS(G13-H13) -> 0
A14: 9 | D14: =ABS(B14-C14) -> 0 | F14: 9 | I14: =ABS(G14-H14) -> 0
A15: 10 | D15: =ABS(B15-C15) -> 0 | F15: 10 | I15: =ABS(G15-H15) -> 0
A16: 11 | D16: =ABS(B16-C16) -> 0 | F16: 11 | I16: =ABS(G16-H16) -> 0
A17: 12 | D17: =ABS(B17-C17) -> 0 | F17: 12 | I17: =ABS(G17-H17) -> 0
A18: 13 | D18: =ABS(B18-C18) -> 0 | F18: 13 | I18: =ABS(G18-H18) -> 0
A19: 14 | D19: =ABS(B19-C19) -> 0 | F19: 14 | I19: =ABS(G19-H19) -> 0
A20: 15 | D20: =ABS(B20-C20) -> 0 | F20: 15 | I20: =ABS(G20-H20) -> 0
A21: 16 | D21: =ABS(B21-C21) -> 0 | F21: 16 | I21: =ABS(G21-H21) -> 0
A22: 17 | D22: =ABS(B22-C22) -> 0 | F22: 17 | I22: =ABS(G22-H22) -> 0
A23: 18 | D23: =ABS(B23-C23) -> 0 | F23: 18 | I23: =ABS(G23-H23) -> 0
A24: 19 | D24: =ABS(B24-C24) -> 0 | F24: 19 | I24: =ABS(G24-H24) -> 0
... A165: 160 | D165: =ABS(B165-C165) -> 0 | F165: 160 | I165: =ABS(G165-H165) -> 0

Sheet HC Sag Uniformity
B1: Horizontal | C1: Vertical
A2: Fractional Uniformity | B2: =COUNTIF(D6:D165, "<"&0.1*C6)/160 -> 0 | C2: =COUNTIF(I6:I165, "<"&0.1*H6)/160 -> 0
A4: Horizontal | F4: Vertical
A5: Pixel | B5: Profile Data | C5: Central ROI Mean | D5: Abs Difference | F5: Pixel | G5: Profile Data | H5: Central ROI Mean | I5: Abs Difference
A6: 1 | D6: =ABS(B6-C6) -> 0 | F6: 1 | I6: =ABS(G6-H6) -> 0
A7: 2 | D7: =ABS(B7-C7) -> 0 | F7: 2 | I7: =ABS(G7-H7) -> 0
A8: 3 | D8: =ABS(B8-C8) -> 0 | F8: 3 | I8: =ABS(G8-H8) -> 0
A9: 4 | D9: =ABS(B9-C9) -> 0 | F9: 4 | I9: =ABS(G9-H9) -> 0
A10: 5 | D10: =ABS(B10-C10) -> 0 | F10: 5 | I10: =ABS(G10-H10) -> 0
A11: 6 | D11: =ABS(B11-C11) -> 0 | F11: 6 | I11: =ABS(G11-H11) -> 0
A12: 7 | D12: =ABS(B12-C12) -> 0 | F12: 7 | I12: =ABS(G12-H12) -> 0 | S12: HC_SAG_UNIFORMITY_ROIs
A13: 8 | D13: =ABS(B13-C13) -> 0 | F13: 8 | I13: =ABS(G13-H13) -> 0
A14: 9 | D14: =ABS(B14-C14) -> 0 | F14: 9 | I14: =ABS(G14-H14) -> 0
A15: 10 | D15: =ABS(B15-C15) -> 0 | F15: 10 | I15: =ABS(G15-H15) -> 0
A16: 11 | D16: =ABS(B16-C16) -> 0 | F16: 11 | I16: =ABS(G16-H16) -> 0
A17: 12 | D17: =ABS(B17-C17) -> 0 | F17: 12 | I17: =ABS(G17-H17) -> 0
A18: 13 | D18: =ABS(B18-C18) -> 0 | F18: 13 | I18: =ABS(G18-H18) -> 0
A19: 14 | D19: =ABS(B19-C19) -> 0 | F19: 14 | I19: =ABS(G19-H19) -> 0
A20: 15 | D20: =ABS(B20-C20) -> 0 | F20: 15 | I20: =ABS(G20-H20) -> 0
A21: 16 | D21: =ABS(B21-C21) -> 0 | F21: 16 | I21: =ABS(G21-H21) -> 0
A22: 17 | D22: =ABS(B22-C22) -> 0 | F22: 17 | I22: =ABS(G22-H22) -> 0
A23: 18 | D23: =ABS(B23-C23) -> 0 | F23: 18 | I23: =ABS(G23-H23) -> 0
A24: 19 | D24: =ABS(B24-C24) -> 0 | F24: 19 | I24: =ABS(G24-H24) -> 0
... A165: 160 | D165: =ABS(B165-C165) -> 0 | F165: 160 | I165: =ABS(G165-H165) -> 0

Sheet HC Cor Uniformity
B1: Horizontal | C1: Vertical
A2: Fractional Uniformity | B2: =COUNTIF(D6:D165, "<"&0.1*C6)/160 -> 0 | C2: =COUNTIF(I6:I165, "<"&0.1*H6)/160 -> 0
A4: Horizontal | F4: Vertical
A5: Pixel | B5: Profile Data | C5: Central ROI Mean | D5: Abs Difference | F5: Pixel | G5: Profile Data | H5: Central ROI Mean | I5: Abs Difference
A6: 1 | D6: =ABS(B6-C6) -> 0 | F6: 1 | I6: =ABS(G6-H6) -> 0
A7: 2 | D7: =ABS(B7-C7) -> 0 | F7: 2 | I7: =ABS(G7-H7) -> 0
A8: 3 | D8: =ABS(B8-C8) -> 0 | F8: 3 | I8: =ABS(G8-H8) -> 0
A9: 4 | D9: =ABS(B9-C9) -> 0 | F9: 4 | I9: =ABS(G9-H9) -> 0
A10: 5 | D10: =ABS(B10-C10) -> 0 | F10: 5 | I10: =ABS(G10-H10) -> 0
A11: 6 | D11: =ABS(B11-C11) -> 0 | F11: 6 | I11: =ABS(G11-H11) -> 0
A12: 7 | D12: =ABS(B12-C12) -> 0 | F12: 7 | I12: =ABS(G12-H12) -> 0 | S12: HC_COR_UNIFORMITY_ROIs
A13: 8 | D13: =ABS(B13-C13) -> 0 | F13: 8 | I13: =ABS(G13-H13) -> 0
A14: 9 | D14: =ABS(B14-C14) -> 0 | F14: 9 | I14: =ABS(G14-H14) -> 0
A15: 10 | D15: =ABS(B15-C15) -> 0 | F15: 10 | I15: =ABS(G15-H15) -> 0
A16: 11 | D16: =ABS(B16-C16) -> 0 | F16: 11 | I16: =ABS(G16-H16) -> 0
A17: 12 | D17: =ABS(B17-C17) -> 0 | F17: 12 | I17: =ABS(G17-H17) -> 0
A18: 13 | D18: =ABS(B18-C18) -> 0 | F18: 13 | I18: =ABS(G18-H18) -> 0
A19: 14 | D19: =ABS(B19-C19) -> 0 | F19: 14 | I19: =ABS(G19-H19) -> 0
A20: 15 | D20: =ABS(B20-C20) -> 0 | F20: 15 | I20: =ABS(G20-H20) -> 0
A21: 16 | D21: =ABS(B21-C21) -> 0 | F21: 16 | I21: =ABS(G21-H21) -> 0
A22: 17 | D22: =ABS(B22-C22) -> 0 | F22: 17 | I22: =ABS(G22-H22) -> 0
A23: 18 | D23: =ABS(B23-C23) -> 0 | F23: 18 | I23: =ABS(G23-H23) -> 0
A24: 19 | D24: =ABS(B24-C24) -> 0 | F24: 19 | I24: =ABS(G24-H24) -> 0
... A165: 160 | D165: =ABS(B165-C165) -> 0 | F165: 160 | I165: =ABS(G165-H165) -> 0

Sheet Geometric
A1: Geometric Linearity and Distortion
A3: Imaging Planes
B4: Transverse | C4: Sagittal | D4: Coronal | E4: Average | F4: Standard Deviation
A5: Distance (mm) | B5: =AVERAGE(B17:B22) -> #DIV/0! | C5: =AVERAGE(F17:F22) -> #DIV/0! | D5: =AVERAGE(J17:J22) -> #DIV/0! | E5: =AVERAGE(B5:D5) -> #DIV/0! | F5: =STDEV(B17:B22,F17:F22,J18:J22) -> #DIV/0!
A6: Distortion (%) | B6: =100*STDEV(B17:B22)/B5 -> #DIV/0! | C6: =100*STDEV(F17:F22)/C5 -> #DIV/0! | D6: =100*STDEV(J17:J22)/D5 -> #DIV/0! | E6: =AVERAGE(B6:D6) -> #DIV/0!
A8: Gradient Directions
B9: x-direction | C9: y-direction | D9: z-direction | E9: Average | F9: Standard Deviation
A10: Distance (mm) | B10: =AVERAGE(B17:B19,J17:J19) -> #DIV/0! | C10: =AVERAGE(B20:B22,F17:F19) -> #DIV/0! | D10: =AVERAGE(F20:F22,J20:J22) -> #DIV/0! | E10: =AVERAGE(B10:D10) -> #DIV/0! | F10: =F5 -> #DIV/0!
A11: Distortion (%) | B11: =100*STDEV(B17:B19,J17:J19)/B10 -> #DIV/0! | C11: =100*STDEV(B20:B22,F17:F19)/C10 -> #DIV/0! | D11: =100*STDEV(F20:F22,J20:J22)/E10 -> #DIV/0! | E11: =AVERAGE(B11:D11) -> #DIV/0!
A13: Distance between rods (mm) | B13: 120
A15: Plane: Transverse | E15: Plane: Sagittal | I15: Plane: Coronal
B16: Measured Distance (mm) | C16: Error (mm) | F16: Measured Distance (mm) | G16: Error (mm) | J16: Measured Distance (mm) | K16: Error (mm)
A17: Rod 1 to Rod 3 | C17: =B17-rod_dist_ -> -120 | E17: Rod 1 to Rod 3 | G17: =F17-rod_dist_ -> -120 | I17: Rod 1 to Rod 3 | K17: =J17-rod_dist_ -> -120
A18: Rod 4 to Rod 6 | C18: =B18-rod_dist_ -> -120 | E18: Rod 4 to Rod 6 | G18: =F18-rod_dist_ -> -120 | I18: Rod 4 to Rod 6 | K18: =J18-rod_dist_ -> -120
A19: Rod 7 to Rod 9 | C19: =B19-rod_dist_ -> -120 | E19: Rod 7 to Rod 9 | G19: =F19-rod_dist_ -> -120 | I19: Rod 7 to Rod 9 | K19: =J19-rod_dist_ -> -120
A20: Rod 1 to Rod 7 | C20: =B20-rod_dist_ -> -120 | E20: Rod 1 to Rod 7 | G20: =F20-rod_dist_ -> -120 | I20: Rod 1 to Rod 7 | K20: =J20-rod_dist_ -> -120
A21: Rod 2 to Rod 8 | C21: =B21-rod_dist_ -> -120 | E21: Rod 2 to Rod 8 | G21: =F21-rod_dist_ -> -120 | I21: Rod 2 to Rod 8 | K21: =J21-rod_dist_ -> -120
A22: Rod 3 to Rod 9 | C22: =B22-rod_dist_ -> -120 | E22: Rod 3 to Rod 9 | G22: =F22-rod_dist_ -> -120 | I22: Rod 3 to Rod 9 | K22: =J22-rod_dist_ -> -120
A37: BC_TRA_GEOMETRIC_LINEARITY_AND_DISTORTION_LINES | D37: BC_SAG_GEOMETRIC_LINEARITY_AND_DISTORTION_LINES | H37: BC_COR_GEOMETRIC_LINEARITY_AND_DISTORTION_LINES

Sheet Slice Width
A1: Slice Width
A3: Slice width (mm)
A4: Nominal | B4: Transverse | C4: Sagittal | D4: Coronal | E4: Average | F4: Standard Deviation
A5: 5 | B5: =AVERAGE(FWHM_tra_1_,FWHM_tra_2_)*Dx_/SF_ -> 0 | C5: =AVERAGE(FWHM_sag_1_,FWHM_sag_2_)*Dx_/SF_ -> 0 | D5: =AVERAGE(FWHM_cor_1_,FWHM_cor_2_)*Dx_/SF_ -> 0 | E5: =AVERAGE(B5:D5) -> 0 | F5: =STDEV(B5:D5) -> 0
A7: Input Parameters | B7: Value
A8: Frequency encode matrix size | B8: 256
A9: Field-of-view (mm) | B9: 256
A11: Fixed Parameters | B11: Value
A12: Angle of plates in test object (deg) | B12: 11.3
A14: Calculated Parameters | B14: Value
A15: Stretch factor | B15: =1/TAN(PI()*theta_/180) -> 5.0045111
A16: Voxel size in the frequency encode direction (mm) | B16: =N_fe_/FOV_ -> 1
A17: FWHM transverse profile 1 (pixels) | B17: ='Tra Slice Width'!B8 -> 0
A18: FWHM transverse profile 2 (pixels) | B18: ='Tra Slice Width'!B9 -> 0
A19: FWHM sagittal profile 1 (pixels) | B19: ='Sag Slice Width'!B8 -> 0
A20: FWHM sagittal profile 2 (pixels) | B20: ='Sag Slice Width'!B9 -> 0
A21: FWHM coronal profile 1 (pixels) | B21: ='Cor Slice Width'!B8 -> 0
A22: FWHM coronal profile 2 (pixels) | B22: ='Cor Slice Width'!B9 -> 0

Sheet Tra Slice Width
A1: Fitting Parameters | B1: Value
A2: Manual offset for baseline of profile 1 | B2: 0
A3: Manual offset for minimum of profile 1 | B3: 25
A4: Manual offset for baseline of profile 2 | B4: 0
A5: Manual offset for minimum of profile 2 | B5: 25
A7: Calculated Parameters | B7: Value
A8: FWHM profile 1 (pixels) | B8: =COUNTIF(B12:B131, "<"&B135) -> 0
A9: FWHM profile 2 (pixels) | B9: =COUNTIF(C12:C131, "<"&C135) -> 0 | N9: BC_TRA_SLICE_WIDTH_ROIs
A11: Pixel | B11: Profile 1 | C11: Profile 2
A12: 0
A13: 1
A14: 2
A15: 3
A16: 4
A17: 5
A18: 6
A19: 7
A20: 8
A21: 9
A22: 10
A23: 11
... A131: 119
A133: Baseline | B133: =AVERAGE(B12:B42,B101:B131)+profile_1_baseline_offset_ -> #DIV/0! | C133: =AVERAGE(C12:C42,C101:C131)+profile_2_baseline_offset_ -> #DIV/0!
A134: Minimum | B134: =MIN(B12:B131)+_xlfn.SINGLE(profile_1_min_offset_) -> 25 | C134: =MIN(C12:C131)+_xlfn.SINGLE(profile_2_min_offset_) -> 25
A135: Half Minimum | B135: =B134+(B133-B134)/2 -> #DIV/0! | C135: =C134+(C133-C134)/2 -> #DIV/0!

Sheet Sag Slice Width
A1: Fitting Parameters | B1: Value
A2: Manual offset for baseline of profile 1 | B2: 0
A3: Manual offset for minimum of profile 1 | B3: 25
A4: Manual offset for baseline of profile 2 | B4: 0
A5: Manual offset for minimum of profile 2 | B5: 25
A7: Calculated Parameters | B7: Value
A8: FWHM profile 1 (pixels) | B8: =COUNTIF(B12:B131, "<"&B135) -> 0
A9: FWHM profile 2 (pixels) | B9: =COUNTIF(C12:C131, "<"&C135) -> 0 | N9: BC_SAG_SLICE_WIDTH_ROIs
A11: Pixel | B11: Profile 1 | C11: Profile 2
A12: 0
A13: 1
A14: 2
A15: 3
A16: 4
A17: 5
A18: 6
A19: 7
A20: 8
A21: 9
A22: 10
A23: 11
... A131: 119
A133: Baseline | B133: =AVERAGE(B12:B42,B101:B131)+profile_1_baseline_offset_ -> #DIV/0! | C133: =AVERAGE(C12:C42,C101:C131)+profile_2_baseline_offset_ -> #DIV/0!
A134: Minimum | B134: =MIN(B12:B131)+_xlfn.SINGLE(profile_1_min_offset_) -> 25 | C134: =MIN(C12:C131)+_xlfn.SINGLE(profile_2_min_offset_) -> 25
A135: Half Minimum | B135: =B134+(B133-B134)/2 -> #DIV/0! | C135: =C134+(C133-C134)/2 -> #DIV/0!

Sheet Cor Slice Width
A1: Fitting Parameters | B1: Value
A2: Manual offset for baseline of profile 1 | B2: 10
A3: Manual offset for minimum of profile 1 | B3: 30
A4: Manual offset for baseline of profile 2 | B4: 30
A5: Manual offset for minimum of profile 2 | B5: 10
A7: Calculated Parameters | B7: Value
A8: FWHM profile 1 (pixels) | B8: =COUNTIF(B12:B131, "<"&B135) -> 0
A9: FWHM profile 2 (pixels) | B9: =COUNTIF(C12:C131, "<"&C135) -> 0 | N9: BC_COR_SLICE_WIDTH_ROIs
A11: Pixel | B11: Profile 1 | C11: Profile 2
A12: 0
A13: 1
A14: 2
A15: 3
A16: 4
A17: 5
A18: 6
A19: 7
A20: 8
A21: 9
A22: 10
A23: 11
... A131: 119
A133: Baseline | B133: =AVERAGE(B12:B42,B101:B131)+profile_1_baseline_offset_ -> #DIV/0! | C133: =AVERAGE(C12:C42,C101:C131)+profile_2_baseline_offset_ -> #DIV/0!
A134: Minimum | B134: =MIN(B12:B131)+_xlfn.SINGLE(profile_1_min_offset_) -> 30 | C134: =MIN(C12:C131)+_xlfn.SINGLE(profile_2_min_offset_) -> 10
A135: Half Minimum | B135: =B134+(B133-B134)/2 -> #DIV/0! | C135: =C134+(C133-C134)/2 -> #DIV/0!

Sheet Slice Position
A1: Slice Position
N2: BC_TRA_SLICE_POSITION_LINES
A3: Mean error + Std Dev Error (mm) | B3: Mean Error (mm) | C3: Mean error - Std Dev Error (mm) | D3: Maximum (absolute) Error (mm)
A4: =H45+H46 -> #DIV/0! | B4: =H45 -> #DIV/0! | C4: =H45-H46 -> #DIV/0! | D4: =I47 -> 0
A6: Input Parameters | B6: Values
A7: Slice thickness (mm)
A8: Slice gap (mm)
A9: Angled rod separation (mm) | B9: 8
A10: Distance between rods (mm) | B10: 120
A12: Calculated Parameters | B12: Values
A13: Slice offset (mm) | B13: =(SUM(F21:F39)-(slice_thk_+slice_gap_)*SUM(A21:A39))/19 -> 0
A16: Slice | B16: Distance (mm) | C16: Mean Test Object Distance (mm) | D16: Correction Factor | E16: Sign | F16: Slice Position (measured) | G16: Slice Position (calculated) | H16: Slice Position Error (mm) | I16: Absolute Error
A17: 1 | D17: =IF(ISBLANK(B17),"",rda_/C17) | E17: -1 | F17: =IF(ISBLANK(B17),"",E17*SQRT((B17*D17)^2-angled_rod_sep_^2)/2) | G17: =IF(ISBLANK(B17),"",A17*(slice_thk_+slice_gap_)+slice_offset_) | H17: =IF(ISBLANK(B17),"",G17-F17) | I17: =IF(ISBLANK(B17),"",ABS(H17))
A18: 2 | D18: =IF(ISBLANK(B18),"",rda_/C18) | E18: -1 | F18: =IF(ISBLANK(B18),"",E18*SQRT((B18*D18)^2-angled_rod_sep_^2)/2) | G18: =IF(ISBLANK(B18),"",A18*(slice_thk_+slice_gap_)+slice_offset_) | H18: =IF(ISBLANK(B18),"",G18-F18) | I18: =IF(ISBLANK(B18),"",ABS(H18))
A19: 3 | D19: =IF(ISBLANK(B19),"",rda_/C19) | E19: -1 | F19: =IF(ISBLANK(B19),"",E19*SQRT((B19*D19)^2-angled_rod_sep_^2)/2) | G19: =IF(ISBLANK(B19),"",A19*(slice_thk_+slice_gap_)+slice_offset_) | H19: =IF(ISBLANK(B19),"",G19-F19) | I19: =IF(ISBLANK(B19),"",ABS(H19))
A20: 4 | D20: =IF(ISBLANK(B20),"",rda_/C20) | E20: -1 | F20: =IF(ISBLANK(B20),"",E20*SQRT((B20*D20)^2-angled_rod_sep_^2)/2) | G20: =IF(ISBLANK(B20),"",A20*(slice_thk_+slice_gap_)+slice_offset_) | H20: =IF(ISBLANK(B20),"",G20-F20) | I20: =IF(ISBLANK(B20),"",ABS(H20))
A21: 5 | D21: =IF(ISBLANK(B21),"",rda_/C21) | E21: -1 | F21: =IF(ISBLANK(B21),"",E21*SQRT((B21*D21)^2-angled_rod_sep_^2)/2) | G21: =IF(ISBLANK(B21),"",A21*(slice_thk_+slice_gap_)+slice_offset_) | H21: =IF(ISBLANK(B21),"",G21-F21) | I21: =IF(ISBLANK(B21),"",ABS(H21))
A22: 6 | D22: =IF(ISBLANK(B22),"",rda_/C22) | E22: -1 | F22: =IF(ISBLANK(B22),"",E22*SQRT((B22*D22)^2-angled_rod_sep_^2)/2) | G22: {=IF(ISBLANK(B22),"",A22*(slice_thk_+slice_gap_)+slice_offset_)} | H22: =IF(ISBLANK(B22),"",G22-F22) | I22: =IF(ISBLANK(B22),"",ABS(H22))
A23: 7 | D23: =IF(ISBLANK(B23),"",rda_/C23) | E23: -1 | F23: =IF(ISBLANK(B23),"",E23*SQRT((B23*D23)^2-angled_rod_sep_^2)/2) | G23: =IF(ISBLANK(B23),"",A23*(slice_thk_+slice_gap_)+slice_offset_) | H23: =IF(ISBLANK(B23),"",G23-F23) | I23: =IF(ISBLANK(B23),"",ABS(H23))
A24: 8 | D24: =IF(ISBLANK(B24),"",rda_/C24) | E24: -1 | F24: =IF(ISBLANK(B24),"",E24*SQRT((B24*D24)^2-angled_rod_sep_^2)/2) | G24: =IF(ISBLANK(B24),"",A24*(slice_thk_+slice_gap_)+slice_offset_) | H24: =IF(ISBLANK(B24),"",G24-F24) | I24: =IF(ISBLANK(B24),"",ABS(H24))
A25: 9 | D25: =IF(ISBLANK(B25),"",rda_/C25) | E25: -1 | F25: =IF(ISBLANK(B25),"",E25*SQRT((B25*D25)^2-angled_rod_sep_^2)/2) | G25: =IF(ISBLANK(B25),"",A25*(slice_thk_+slice_gap_)+slice_offset_) | H25: =IF(ISBLANK(B25),"",G25-F25) | I25: =IF(ISBLANK(B25),"",ABS(H25))
A26: 10 | D26: =IF(ISBLANK(B26),"",rda_/C26) | E26: -1 | F26: =IF(ISBLANK(B26),"",E26*SQRT((B26*D26)^2-angled_rod_sep_^2)/2) | G26: =IF(ISBLANK(B26),"",A26*(slice_thk_+slice_gap_)+slice_offset_) | H26: =IF(ISBLANK(B26),"",G26-F26) | I26: =IF(ISBLANK(B26),"",ABS(H26))
A27: 11 | D27: =IF(ISBLANK(B27),"",rda_/C27) | E27: -1 | F27: =IF(ISBLANK(B27),"",E27*SQRT((B27*D27)^2-angled_rod_sep_^2)/2) | G27: =IF(ISBLANK(B27),"",A27*(slice_thk_+slice_gap_)+slice_offset_) | H27: =IF(ISBLANK(B27),"",G27-F27) | I27: =IF(ISBLANK(B27),"",ABS(H27))
A28: 12 | D28: =IF(ISBLANK(B28),"",rda_/C28) | E28: -1 | F28: =IF(ISBLANK(B28),"",E28*SQRT((B28*D28)^2-angled_rod_sep_^2)/2) | G28: =IF(ISBLANK(B28),"",A28*(slice_thk_+slice_gap_)+slice_offset_) | H28: =IF(ISBLANK(B28),"",G28-F28) | I28: =IF(ISBLANK(B28),"",ABS(H28))
A29: 13 | D29: =IF(ISBLANK(B29),"",rda_/C29) | E29: -1 | F29: =IF(ISBLANK(B29),"",E29*SQRT((B29*D29)^2-angled_rod_sep_^2)/2) | G29: =IF(ISBLANK(B29),"",A29*(slice_thk_+slice_gap_)+slice_offset_) | H29: =IF(ISBLANK(B29),"",G29-F29) | I29: =IF(ISBLANK(B29),"",ABS(H29))
A30: 14 | D30: =IF(ISBLANK(B30),"",rda_/C30) | E30: 1
A31: 15 | D31: =IF(ISBLANK(B31),"",rda_/C31) | E31: 1 | F31: =IF(ISBLANK(B31),"",E31*SQRT((B31*D31)^2-angled_rod_sep_^2)/2) | G31: =IF(ISBLANK(B31),"",A31*(slice_thk_+slice_gap_)+slice_offset_) | H31: =IF(ISBLANK(B31),"",G31-F31) | I31: =IF(ISBLANK(B31),"",ABS(H31))
A32: 16 | D32: =IF(ISBLANK(B32),"",rda_/C32) | E32: 1 | F32: =IF(ISBLANK(B32),"",E32*SQRT((B32*D32)^2-angled_rod_sep_^2)/2) | G32: =IF(ISBLANK(B32),"",A32*(slice_thk_+slice_gap_)+slice_offset_) | H32: =IF(ISBLANK(B32),"",G32-F32) | I32: =IF(ISBLANK(B32),"",ABS(H32))
A33: 17 | D33: =IF(ISBLANK(B33),"",rda_/C33) | E33: 1 | F33: =IF(ISBLANK(B33),"",E33*SQRT((B33*D33)^2-angled_rod_sep_^2)/2) | G33: =IF(ISBLANK(B33),"",A33*(slice_thk_+slice_gap_)+slice_offset_) | H33: =IF(ISBLANK(B33),"",G33-F33) | I33: =IF(ISBLANK(B33),"",ABS(H33))
A34: 18 | D34: =IF(ISBLANK(B34),"",rda_/C34) | E34: 1 | F34: =IF(ISBLANK(B34),"",E34*SQRT((B34*D34)^2-angled_rod_sep_^2)/2) | G34: =IF(ISBLANK(B34),"",A34*(slice_thk_+slice_gap_)+slice_offset_) | H34: =IF(ISBLANK(B34),"",G34-F34) | I34: =IF(ISBLANK(B34),"",ABS(H34))
A35: 19 | D35: =IF(ISBLANK(B35),"",rda_/C35) | E35: 1 | F35: =IF(ISBLANK(B35),"",E35*SQRT((B35*D35)^2-angled_rod_sep_^2)/2) | G35: =IF(ISBLANK(B35),"",A35*(slice_thk_+slice_gap_)+slice_offset_) | H35: =IF(ISBLANK(B35),"",G35-F35) | I35: =IF(ISBLANK(B35),"",ABS(H35))
A36: 20 | D36: =IF(ISBLANK(B36),"",rda_/C36) | E36: 1 | F36: =IF(ISBLANK(B36),"",E36*SQRT((B36*D36)^2-angled_rod_sep_^2)/2) | G36: =IF(ISBLANK(B36),"",A36*(slice_thk_+slice_gap_)+slice_offset_) | H36: =IF(ISBLANK(B36),"",G36-F36) | I36: =IF(ISBLANK(B36),"",ABS(H36))
A37: 21 | D37: =IF(ISBLANK(B37),"",rda_/C37) | E37: 1 | F37: =IF(ISBLANK(B37),"",E37*SQRT((B37*D37)^2-angled_rod_sep_^2)/2) | G37: =IF(ISBLANK(B37),"",A37*(slice_thk_+slice_gap_)+slice_offset_) | H37: =IF(ISBLANK(B37),"",G37-F37) | I37: =IF(ISBLANK(B37),"",ABS(H37))
A38: 22 | D38: =IF(ISBLANK(B38),"",rda_/C38) | E38: 1 | F38: =IF(ISBLANK(B38),"",E38*SQRT((B38*D38)^2-angled_rod_sep_^2)/2) | G38: =IF(ISBLANK(B38),"",A38*(slice_thk_+slice_gap_)+slice_offset_) | H38: =IF(ISBLANK(B38),"",G38-F38) | I38: =IF(ISBLANK(B38),"",ABS(H38))
A39: 23 | D39: =IF(ISBLANK(B39),"",rda_/C39) | E39: 1 | F39: =IF(ISBLANK(B39),"",E39*SQRT((B39*D39)^2-angled_rod_sep_^2)/2) | G39: =IF(ISBLANK(B39),"",A39*(slice_thk_+slice_gap_)+slice_offset_) | H39: =IF(ISBLANK(B39),"",G39-F39) | I39: =IF(ISBLANK(B39),"",ABS(H39))
A40: 24 | D40: =IF(ISBLANK(B40),"",rda_/C40) | E40: 1 | F40: =IF(ISBLANK(B40),"",E40*SQRT((B40*D40)^2-angled_rod_sep_^2)/2) | G40: =IF(ISBLANK(B40),"",A40*(slice_thk_+slice_gap_)+slice_offset_) | H40: =IF(ISBLANK(B40),"",G40-F40) | I40: =IF(ISBLANK(B40),"",ABS(H40))
A41: 25 | D41: =IF(ISBLANK(B41),"",rda_/C41) | E41: 1 | F41: =IF(ISBLANK(B41),"",E41*SQRT((B41*D41)^2-angled_rod_sep_^2)/2) | G41: =IF(ISBLANK(B41),"",A41*(slice_thk_+slice_gap_)+slice_offset_) | H41: =IF(ISBLANK(B41),"",G41-F41) | I41: =IF(ISBLANK(B41),"",ABS(H41))
A42: 26 | D42: =IF(ISBLANK(B42),"",rda_/C42) | E42: 1 | F42: =IF(ISBLANK(B42),"",E42*SQRT((B42*D42)^2-angled_rod_sep_^2)/2) | G42: =IF(ISBLANK(B42),"",A42*(slice_thk_+slice_gap_)+slice_offset_) | H42: =IF(ISBLANK(B42),"",G42-F42) | I42: =IF(ISBLANK(B42),"",ABS(H42))
A43: 27 | D43: =IF(ISBLANK(B43),"",rda_/C43) | E43: 1 | F43: =IF(ISBLANK(B43),"",E43*SQRT((B43*D43)^2-angled_rod_sep_^2)/2) | G43: =IF(ISBLANK(B43),"",A43*(slice_thk_+slice_gap_)+slice_offset_) | H43: =IF(ISBLANK(B43),"",G43-F43) | I43: =IF(ISBLANK(B43),"",ABS(H43))
G45: Mean | H45: =AVERAGE(H17:H43) -> #DIV/0!
...

Sheet EPI Stability
A1: EPI Stability
A3: Max signal | B3: Min signal | C3: Delta | D3: Mean signal | E3: Delta/Mean
A4: =MAX(B12:B111) -> 0 | B4: =MIN(B12:B111) -> 0 | C4: =A4-B4 -> 0 | D4: =AVERAGE(B12:B111) -> #DIV/0! | E4: =C4/D4 -> #DIV/0!
B6: Per Set of 25 images
B7: 1 to 25 | C7: 26 to 50 | D7: 51 to 75 | E7: 76 to 100
A8: Mean Signal | B8: =AVERAGE(B12:B36) -> #DIV/0! | C8: =AVERAGE(B37:B61) -> #DIV/0! | D8: =AVERAGE(B62:B86) -> #DIV/0! | E8: =AVERAGE(B87:B111) -> #DIV/0!
A9: Signal Standard Deviation | B9: =STDEV(B12:B36) -> #DIV/0! | C9: =STDEV(B37:B61) -> #DIV/0! | D9: =STDEV(B62:B86) -> #DIV/0! | E9: =STDEV(B87:B111) -> #DIV/0!
P10: HC_TRA_EPI_STABILITY_ROI
A11: Image Set | B11: Signal
A12: Images 1-25
A13: Images 1-25
A14: Images 1-25
A15: Images 1-25
A16: Images 1-25
A17: Images 1-25
A18: Images 1-25
A19: Images 1-25
A20: Images 1-25
A21: Images 1-25
A22: Images 1-25
A23: Images 1-25
... A111: Images 76-100

Sheet Tables for Report
A1: Input Parameters | B1: Value
A2: System Name
A5: Table 1: Body Coil NSNR | G5: Table 3: Body Coil Fractional Uniformity | N5: Table 5: Geometric Linearity for 3 Gradient Directions | U5: Table 7: Measured Slice Widths for a Nominal 5 mm Slice | AB5: Table 8: Slice Position Error Measurements | AH5: Table 9: EPI Stability
A6: Plane | B6: Axial | C6: Sagittal | D6: Coronal | E6: Mean | G6: Gradient Direction | H6: X | I6: Y | J6: Z | K6: Mean | L6: Standard Deviation | N6: Gradient Direction | O6: X | P6: Y | Q6: Z | R6: Mean | S6: Standard Deviation | U6: Plane | V6: Axial | W6: Sagittal | X6: Coronal | Y6: Mean | Z6: Standard Deviation | AC6: Mean Error + Std Dev Error (mm) | AD6: Mean Error (mm) | AE6: Mean Error - Std Dev Error (mm) | AF6: Maximum (absolute) Error (mm) | AI6: Max signal | AJ6: Min signal | AK6: Delta | AL6: Mean signal | AM6: Delta/Mean
A7: =sys_name_ -> 0 | B7: ='BC SNR'!B5 -> #DIV/0! | C7: ='BC SNR'!C5 -> #DIV/0! | D7: ='BC SNR'!D5 -> #DIV/0! | E7: ='BC SNR'!E5 -> #DIV/0! | G7: =sys_name_ -> 0 | H7: ='BC Uniformity'!A4 -> 0 | I7: ='BC Uniformity'!B4 -> 0 | J7: ='BC Uniformity'!C4 -> 0 | K7: ='BC Uniformity'!D4 -> 0 | L7: ='BC Uniformity'!E4 -> 0 | N7: =sys_name_ -> 0 | O7: =Geometric!B10 -> #DIV/0! | P7: =Geometric!C10 -> #DIV/0! | Q7: =Geometric!D10 -> #DIV/0! | R7: =Geometric!E10 -> #DIV/0! | S7: =Geometric!F10 -> #DIV/0! | U7: =sys_name_ -> 0 | V7: ='Slice Width'!B5 -> 0 | W7: ='Slice Width'!C5 -> 0 | X7: ='Slice Width'!D5 -> 0 | Y7: ='Slice Width'!E5 -> 0 | Z7: ='Slice Width'!F5 -> 0 | AB7: =sys_name_ -> 0 | AC7: ='Slice Position'!A4 -> #DIV/0! | AD7: ='Slice Position'!B4 -> #DIV/0! | AE7: ='Slice Position'!C4 -> #DIV/0! | AF7: ='Slice Position'!D4 -> 0 | AH7: =sys_name_ -> 0 | AI7: ='EPI Stability'!A4 -> 0 | AJ7: ='EPI Stability'!B4 -> 0 | AK7: ='EPI Stability'!C4 -> 0 | AL7: ='EPI Stability'!D4 -> #DIV/0! | AM7: ='EPI Stability'!E4 -> #DIV/0!
A9: Table 2: Head Coil NSNR | G9: Table 4: Head Coil Fractional Uniformity | N9: Table 6: Geometric Distortion (%) for 3 Gradient Directions
A10: Plane | B10: Axial | C10: Sagittal | D10: Coronal | E10: Mean | G10: Gradient Direction | H10: X | I10: Y | J10: Z | K10: Mean | L10: Standard Deviation | N10: Gradient Direction | O10: X | P10: Y | Q10: Z | R10: Mean
A11: =sys_name_ -> 0 | B11: ='HC SNR'!B5 -> #DIV/0! | C11: ='HC SNR'!C5 -> #DIV/0! | D11: ='HC SNR'!D5 -> #DIV/0! | E11: ='HC SNR'!E5 -> #DIV/0! | G11: =sys_name_ -> 0 | H11: ='HC Uniformity'!A4 -> 0 | I11: ='HC Uniformity'!B4 -> 0 | J11: ='HC Uniformity'!C4 -> 0 | K11: ='HC Uniformity'!D4 -> 0 | L11: ='HC Uniformity'!E4 -> 0 | N11: =sys_name_ -> 0 | O11: =Geometric!B11 -> #DIV/0! | P11: =Geometric!C11 -> #DIV/0! | Q11: =Geometric!D11 -> #DIV/0! | R11: =Geometric!E11 -> #DIV/0!
F46: Delta/Mean

Sheet Comparison Charts for Report
A1: Input Parameters | B1: Value
A2: Comparison System Name
B6: Body Coil NSNR
A7: ='Tables for Report'!sys_name_ -> 0 | B7: ='Tables for Report'!E7 -> #DIV/0!
A8: =sys_name_comp_ -> 0
B10: Head Coil NSNR
A11: ='Tables for Report'!sys_name_ -> 0 | B11: ='Tables for Report'!E11 -> #DIV/0!
A12: =sys_name_comp_ -> 0
B14: Body Coil Mean Uniformity
A15: ='Tables for Report'!sys_name_ -> 0 | B15: ='Tables for Report'!K7 -> 0
A16: =sys_name_comp_ -> 0
B18: Head Coil Mean Uniformity
A19: ='Tables for Report'!sys_name_ -> 0 | B19: ='Tables for Report'!K11 -> 0
A20: =sys_name_comp_ -> 0
B22: Mean Geometric Linearity Error (mm)
A23: ='Tables for Report'!sys_name_ -> 0 | B23: ='Tables for Report'!R7-120 -> #DIV/0!
A24: =sys_name_comp_ -> 0
B26: Mean Geometric Distortion (%)
A27: ='Tables for Report'!sys_name_ -> 0 | B27: ='Tables for Report'!R11 -> #DIV/0!
A28: =sys_name_comp_ -> 0
B30: Slice Width Error (mm)
A31: ='Tables for Report'!sys_name_ -> 0 | B31: ='Tables for Report'!Y7-5 -> -5
A32: =sys_name_comp_ -> 0
